<?xml version="1.0" ?>
<!-- =================================================================================== -->
<!-- |    This document was autogenerated by xacro from src/robu/urdf/example_robot.urdf.xacro | -->
<!-- |    EDITING THIS FILE BY HAND IS NOT RECOMMENDED                                 | -->
<!-- =================================================================================== -->
<robot name="robot">
  <!-- Material Definitions -->
  <material name="grey">
    <color rgba="0.2 0.2 0.2 1"/>
  </material>
  <material name="white">
    <color rgba="1 1 1 1"/>
  </material>
  <material name="orange">
    <color rgba="1 0.3 0.1 1"/>
  </material>
  <material name="blue">
    <color rgba="0 0 1 1"/>
  </material>
  <link name="world"/>
  <!-- base Joint -->
  <link name="base">
    <visual>
      <origin rpy="1.570796326795 0 0" xyz="0 0 0"/>
      <geometry>
        <mesh filename="package://robu/urdf/Z_Achse.stl" scale="0.01 0.01 0.01"/>
      </geometry>
      <material name="blue"/>
    </visual>
    <collision>
      <origin rpy="1.570796326795 0 0" xyz="0 0 2.1"/>
      <geometry>
        <box size="2.5 4.2 2.5"/>
      </geometry>
    </collision>
    <inertial>
      <origin rpy="0 0 0" xyz="0 0 0.05"/>
      <mass value="12"/>
      <inertia ixx="2.26" ixy="0.0" ixz="0.0" iyy="6.26" iyz="0.0" izz="8.5"/>
    </inertial>
  </link>
  <joint name="base_to_world" type="fixed">
    <parent link="world"/>
    <child link="base"/>
    <origin rpy="0 0 0" xyz="0 0 0"/>
  </joint>
  <!-- Z.Achse Segment Joint-->
  <link name="z_achse">
    <visual>
      <origin rpy="4.712388980385 3.14159265359 4.712388980385" xyz="0 0 0 "/>
      <geometry>
        <mesh filename="package://robu/urdf/1_Arm.stl" scale="0.01 0.01 0.01"/>
      </geometry>
      <material name="orange"/>
    </visual>
    <!-- -> Keine Collissions weil das Bauteil in der Z-Achse ist. -->
    <inertial>
      <origin rpy="0 0 0" xyz="0 0 0.05"/>
      <mass value="12"/>
      <inertia ixx="2.26" ixy="0.0" ixz="0.0" iyy="6.26" iyz="0.0" izz="8.5"/>
    </inertial>
  </link>
  <joint name="z_Achse_to_base" type="prismatic">
    <parent link="base"/>
    <child link="z_achse"/>
    <origin rpy="0 0 0" xyz="0 0 0"/>
    <axis xyz="0 0 1"/>
    <limit effort="100" lower="0.5" upper="3.03" velocity="0.1"/>
  </joint>
  <!-- 1 Arm Segment Joint-->
  <link name="1_arm">
    <visual>
      <origin rpy="4.712388980385 3.14159265359 4.712388980385" xyz="0 0 0 "/>
      <geometry>
        <mesh filename="package://robu/urdf/2_Arm.stl" scale="0.01 0.01 0.01"/>
      </geometry>
      <material name="orange"/>
    </visual>
    <collision>
      <origin rpy="1.570796326795 0 0" xyz="0 1 0.65"/>
      <geometry>
        <box size="1 1.35 3.25"/>
      </geometry>
    </collision>
    <inertial>
      <origin rpy="0 0 0" xyz="0 0 0.05"/>
      <mass value="12"/>
      <inertia ixx="2.26" ixy="0.0" ixz="0.0" iyy="6.26" iyz="0.0" izz="8.5"/>
    </inertial>
  </link>
  <joint name="z_achse_to_1_arm" type="revolute">
    <parent link="z_achse"/>
    <child link="1_arm"/>
    <origin rpy="0 0 0" xyz="0 1 -.35"/>
    <axis xyz="0 0 1"/>
    <limit effort="100" lower="-1.5" upper="1.5" velocity="0.1"/>
  </joint>
  <!-- 2 Arm Segment Joint-->
  <link name="2_arm">
    <visual>
      <origin rpy="4.712388980385 0 4.712388980385" xyz="0 0 0 "/>
      <geometry>
        <mesh filename="package://robu/urdf/3_Arm.stl" scale="0.01 0.01 0.01"/>
      </geometry>
      <material name="orange"/>
    </visual>
    <collision>
      <origin rpy="1.570796326795 0 0" xyz="0 1.4 .2"/>
      <geometry>
        <box size="1 .7 2.5"/>
      </geometry>
    </collision>
    <inertial>
      <origin rpy="0 0 0" xyz="0 0 0.05"/>
      <mass value="12"/>
      <inertia ixx="2.26" ixy="0.0" ixz="0.0" iyy="6.26" iyz="0.0" izz="8.5"/>
    </inertial>
  </link>
  <joint name="1_achse_to_2_arm" type="revolute">
    <parent link="1_arm"/>
    <child link="2_arm"/>
    <origin rpy="0 0 0" xyz="0 2.3 1.15"/>
    <axis xyz="0 0 1"/>
    <limit effort="100" lower="-2" upper="2" velocity="0.1"/>
  </joint>
  <!-- greifer Segment Joint-->
  <link name="greifer">
    <visual>
      <origin rpy="1.570796326795 0 4.712388980385" xyz="0 0 0 "/>
      <geometry>
        <mesh filename="package://robu/urdf/Greiferneu.stl" scale="0.01 0.01 0.01"/>
      </geometry>
      <material name="orange"/>
    </visual>
    <collision>
      <origin rpy="1.570796326795 0 0" xyz="0 0 -0.47"/>
      <geometry>
        <box size=".75 1 1"/>
      </geometry>
    </collision>
    <inertial>
      <origin rpy="0 0 0" xyz="0 0 0.05"/>
      <mass value="12"/>
      <inertia ixx="2.26" ixy="0.0" ixz="0.0" iyy="6.26" iyz="0.0" izz="8.5"/>
    </inertial>
  </link>
  <joint name="2_achse_to_greifer" type="continuous">
    <parent link="2_arm"/>
    <child link="greifer"/>
    <origin rpy="0 0 0" xyz="0 2.2 -0.19"/>
    <axis xyz="0 0 1"/>
  </joint>
  <!-- This file demonstrates the use of some <gazebo> tags -->
  <!-- To include it add the following line -->
  <!-- <xacro:include filename="example_gazebo.xacro" /> -->
  <!-- Gazebo is unable to use the same <material> tags that are already in the URDF (that RViz uses). -->
  <!-- Instead, we need to add gazebo tags for our links that refer to Gazebo materials -->
  <gazebo reference="world">
    <material>Gazebo/Green</material>
    <force_color>true</force_color>
  </gazebo>
  <gazebo reference="base">
    <material>Gazebo/Green</material>
    <force_color>true</force_color>
  </gazebo>
  <gazebo reference="z_achse">
    <material>Gazebo/Green</material>
    <force_color>true</force_color>
  </gazebo>
  <gazebo reference="1_arm">
    <material>Gazebo/Green</material>
  </gazebo>
  <gazebo reference="2_arm">
    <material>Gazebo/Green</material>
  </gazebo>
  <gazebo reference="greifer">
    <material>Gazebo/Green</material>
  </gazebo>
  <!-- Gazebo requires the use of plugins to interact with other systems such as ROS. -->
  <!-- This plugin will publish the joint_states for the selected joints 
            (which robot_state_publisher can then use to broadcast the approprate tf). -->
  <plugin filename="libgazebo_ros_joint_state_publisher.so" name="gazebo_ros_joint_state_publisher">
    <update_rate>20</update_rate>
    <joint_name>base_to_world</joint_name>
    <joint_name>z_Achse_to_base</joint_name>
    <joint_name>z_achse_to_1_arm</joint_name>
    <joint_name>1_achse_to_2_arm</joint_name>
    <joint_name>2_achse_to_greifer</joint_name>
  </plugin>
  <!-- This plugin will read a JointTrajectory message from the /set_joint_trajectory topic 
            and move the machine accordingly. It's a bit clunky but it works. -->
  <!-- You'll probably want to add damping to the joints to stop them it flopping around. 
            e.g. <dynamics damping="10.0" friction="10.0"/> -->
  <!-- Here's an example message to publish to test it:
            ros2 topic pub -1 /set_joint_trajectory trajectory_msgs/msg/JointTrajectory  '{header: {frame_id: world}, joint_names: [slider_joint, arm_joint], points: [  {positions: {0.8,0.6}} ]}' -->
  <gazebo>
    <plugin filename="libgazebo_ros_joint_pose_trajectory.so" name="gazebo_ros_joint_pose_trajectory">
      <update_rate>20</update_rate>
    </plugin>
  </gazebo>
  <!-- The next section shows an example of adding a sensor, in this case a depth camera. -->
  <!-- Due to a quirk of how cameras work, an extra joint/link is required to create an
            "optical frame" for the sensor. That isn't the focus for this tutorial, but you can
            look at https://www.ros.org/reps/rep-0103.html#suffix-frames for slightly more information. -->
  <!-- First, create the link and joint for the optical frame -->
  <!--
    <joint name="camera_optical_joint" type="fixed">
        <origin xyz="0 0 0" rpy="-1.571 0 -1.571" />
        <parent link="camera_link" />
        <child link="camera_link_optical" />
    </joint>

    <link name="camera_link_optical"></link>


    <! Add a gazebo tag for the ORIGINAL camera_link (but in the plugin we reference the optical frame so that ROS can orient things correctly) -->
  <!-- Within the gazebo tag we have the sensor tag, and inside that there is (among other things) the camera tag with the camera parameters, 
            and the plugin tag with some extra parameters the plugin needs. -->
  <!-- Note that although visualise is set to true, it won't actually visualise the depth camera in gazebo. To see the preview, 
            try swapping "depth" to "camera"
    
    <gazebo reference="camera_link">
        <sensor type="depth" name="my_camera">
            <update_rate>20</update_rate>
            <visualize>true</visualize>
            <camera name="cam">
                <horizontal_fov>1.3962634</horizontal_fov>
                <image>
                    <width>640</width>
                    <height>480</height>
                    <format>R8B8G8</format>
                </image>
                <clip>
                    <near>0.02</near>
                    <far>300</far>
                </clip>
                <noise>
                    <type>gaussian</type>
                    <mean>0.0</mean>
                    <stddev>0.007</stddev>
                </noise>
            </camera>
            <plugin name="camera_controller" filename="libgazebo_ros_camera.so">
                <frame_name>camera_link_optical</frame_name>
                <min_depth>0.1</min_depth>
                <max_depth>500</max_depth>
            </plugin>
        </sensor>
    </gazebo>
    -->
</robot>
